<?xml version="1.0"?>
<robot xmlns:xacro="http://www.ros.org/wiki/xacro" name="ffw_lg2_leader">
  <xacro:arg name="use_sim" default="false" />
  <xacro:arg name="use_mock_hardware" default="false" />
  <xacro:arg name="mock_sensor_commands" default="false" />
  <xacro:arg name="prefix" default="" />
  <xacro:arg name="leader_left_port" default="/dev/left_leader" />
  <xacro:arg name="leader_right_port" default="/dev/right_leader" />

  <xacro:include filename="$(find ffw_description)/urdf/common/leader/ffw_leader_body.urdf.xacro" />

  <xacro:include filename="$(find ffw_description)/ros2_control/ffw_lg2_leader/ffw_lg2_leader_left.ros2_control.xacro" />

  <xacro:include filename="$(find ffw_description)/ros2_control/ffw_lg2_leader/ffw_lg2_leader_right.ros2_control.xacro" />

  <link name="world"/>

  <xacro:ffw_leader_body parent="$(arg prefix)world" prefix="$(arg prefix)">
    <origin xyz="0 0 0" rpy="0 0 0" />
  </xacro:ffw_leader_body>

  <joint name="$(arg prefix)gripper_l_joint1" type="revolute">
    <origin xyz="0 0 0" rpy="0 0 0"/>
    <parent link="$(arg prefix)arm_l_link7"/>
    <axis xyz="0 1 0"/>
    <child link="$(arg prefix)gripper_l_link1"/>
    <limit velocity="6.5" effort="1000" lower="-6.28" upper="6.28" />
  </joint>
  <link name="$(arg prefix)gripper_l_link1"/>

  <joint name="$(arg prefix)gripper_r_joint1" type="revolute">
    <origin xyz="0 0 0" rpy="0 0 0"/>
    <parent link="$(arg prefix)arm_r_link7"/>
    <axis xyz="0 1 0"/>
    <child link="$(arg prefix)gripper_r_link1"/>
    <limit velocity="6.5" effort="1000" lower="-6.28" upper="6.28" />
  </joint>
  <link name="$(arg prefix)gripper_r_link1"/>

  <xacro:ffw_lg2_leader_left_system
      use_sim="$(arg use_sim)"
      use_mock_hardware="$(arg use_mock_hardware)"
      mock_sensor_commands="$(arg mock_sensor_commands)"
      port_name="$(arg leader_left_port)" />

  <xacro:ffw_lg2_leader_right_system
      use_sim="$(arg use_sim)"
      use_mock_hardware="$(arg use_mock_hardware)"
      mock_sensor_commands="$(arg mock_sensor_commands)"
      port_name="$(arg leader_right_port)" />

</robot>
